<?xml version="1.0" ?>
<robot name="URDF" xmlns:xacro="http://www.ros.org/wiki/xacro">

<xacro:include filename="$(find URDF_description)/urdf/materials.xacro" />
<xacro:include filename="$(find URDF_description)/urdf/URDF.trans" />
<xacro:include filename="$(find URDF_description)/urdf/URDF.gazebo" />

<material name="yellow">
  <color rgba="0.960784 0.666667 0.152941 1"/>
  </material>

<material name="black">
  <color rgba="0 0 0 1"/>
</material>

<material name="red">
  <color rgba="0.8 0 0 1"/>
</material>

<link name="base_link">
  <inertial>
    <origin xyz="4.3120809249783945e-07 -0.002147732163515349 -0.02204770406068121" rpy="0 0 0"/>
    <mass value="18.166946756265844"/>
    <inertia ixx="0.171107" iyy="0.186254" izz="0.033576" ixy="0.0" iyz="-0.000305" ixz="0.0"/>
  </inertial>
  <visual>
    <origin xyz="0 0 0" rpy="0 0 0"/>
    <geometry>
      <mesh filename="meshes/base_link.stl" scale="0.001 0.001 0.001"/>
    </geometry>
    <material name="yellow"/>
  </visual>
  <collision>
    <origin xyz="0 0 0" rpy="0 0 0"/>
    <geometry>
      <mesh filename="meshes/base_link.stl" scale="0.001 0.001 0.001"/>
    </geometry>
  </collision>
</link>

<link name="fr_motor_1">
  <inertial>
    <origin xyz="-0.005768216716589079 -0.009909326541267308 0.030058677479947823" rpy="0 0 0"/>
    <mass value="0.6398393267480108"/>
    <inertia ixx="0.000272" iyy="0.000224" izz="0.000163" ixy="2e-06" iyz="3e-06" ixz="-2e-06"/>
  </inertial>
  <visual>
    <origin xyz="0.057 -0.004647 -0.057101" rpy="0 0 0"/>
    <geometry>
      <mesh filename="meshes/fr_motor_1.stl" scale="0.001 0.001 0.001"/>
    </geometry>
    <material name="black"/>
  </visual>
  <collision>
    <origin xyz="0.057 -0.004647 -0.057101" rpy="0 0 0"/>
    <geometry>
      <mesh filename="meshes/fr_motor_1.stl" scale="0.001 0.001 0.001"/>
    </geometry>
  </collision>
</link>

<link name="lf_motor_1">
  <inertial>
    <origin xyz="0.005768216716588968 -0.009909326541267364 0.030058677480099036" rpy="0 0 0"/>
    <mass value="0.6398393267480068"/>
    <inertia ixx="0.000272" iyy="0.000224" izz="0.000163" ixy="-2e-06" iyz="3e-06" ixz="2e-06"/>
  </inertial>
  <visual>
    <origin xyz="-0.057 -0.004647 -0.057101" rpy="0 0 0"/>
    <geometry>
      <mesh filename="meshes/lf_motor_1.stl" scale="0.001 0.001 0.001"/>
    </geometry>
    <material name="black"/>
  </visual>
  <collision>
    <origin xyz="-0.057 -0.004647 -0.057101" rpy="0 0 0"/>
    <geometry>
      <mesh filename="meshes/lf_motor_1.stl" scale="0.001 0.001 0.001"/>
    </geometry>
  </collision>
</link>

<link name="lr_motor_1">
  <inertial>
    <origin xyz="0.005768216716588996 -0.009909326541268098 -0.03048651188958061" rpy="0 0 0"/>
    <mass value="0.6398393267480067"/>
    <inertia ixx="0.000272" iyy="0.000224" izz="0.000163" ixy="-2e-06" iyz="-0.0" ixz="3e-06"/>
  </inertial>
  <visual>
    <origin xyz="-0.057 -0.004647 0.102199" rpy="0 0 0"/>
    <geometry>
      <mesh filename="meshes/lr_motor_1.stl" scale="0.001 0.001 0.001"/>
    </geometry>
    <material name="black"/>
  </visual>
  <collision>
    <origin xyz="-0.057 -0.004647 0.102199" rpy="0 0 0"/>
    <geometry>
      <mesh filename="meshes/lr_motor_1.stl" scale="0.001 0.001 0.001"/>
    </geometry>
  </collision>
</link>

<link name="rr_motor_1">
  <inertial>
    <origin xyz="-0.005768216716589093 -0.009909326541268037 -0.03048651188973185" rpy="0 0 0"/>
    <mass value="0.6398393267480106"/>
    <inertia ixx="0.000272" iyy="0.000224" izz="0.000163" ixy="2e-06" iyz="-0.0" ixz="-3e-06"/>
  </inertial>
  <visual>
    <origin xyz="0.057 -0.004647 0.102199" rpy="0 0 0"/>
    <geometry>
      <mesh filename="meshes/rr_motor_1.stl" scale="0.001 0.001 0.001"/>
    </geometry>
    <material name="black"/>
  </visual>
  <collision>
    <origin xyz="0.057 -0.004647 0.102199" rpy="0 0 0"/>
    <geometry>
      <mesh filename="meshes/rr_motor_1.stl" scale="0.001 0.001 0.001"/>
    </geometry>
  </collision>
</link>

<link name="lr_femur_1">
  <inertial>
    <origin xyz="-0.009181067698290135 5.715328447314372e-08 -0.0415132400560885" rpy="0 0 0"/>
    <mass value="0.3339508505480859"/>
    <inertia ixx="0.000356" iyy="0.000351" izz="2.2e-05" ixy="0.0" iyz="-0.0" ixz="2e-06"/>
  </inertial>
  <visual>
    <origin xyz="0.0845 -0.004447 0.142799" rpy="0 0 0"/>
    <geometry>
      <mesh filename="meshes/lr_femur_1.stl" scale="0.001 0.001 0.001"/>
    </geometry>
    <material name="yellow"/>
  </visual>
  <collision>
    <origin xyz="0.0845 -0.004447 0.142799" rpy="0 0 0"/>
    <geometry>
      <mesh filename="meshes/lr_femur_1.stl" scale="0.001 0.001 0.001"/>
    </geometry>
  </collision>
</link>

<link name="rr_femur_1">
  <inertial>
    <origin xyz="0.009181067699383441 5.7143211465611465e-08 -0.04151323998476175" rpy="0 0 0"/>
    <mass value="0.33395084853148577"/>
    <inertia ixx="0.000356" iyy="0.000351" izz="2.2e-05" ixy="-0.0" iyz="-0.0" ixz="-2e-06"/>
  </inertial>
  <visual>
    <origin xyz="-0.0845 -0.004447 0.142799" rpy="0 0 0"/>
    <geometry>
      <mesh filename="meshes/rr_femur_1.stl" scale="0.001 0.001 0.001"/>
    </geometry>
    <material name="yellow"/>
  </visual>
  <collision>
    <origin xyz="-0.0845 -0.004447 0.142799" rpy="0 0 0"/>
    <geometry>
      <mesh filename="meshes/rr_femur_1.stl" scale="0.001 0.001 0.001"/>
    </geometry>
  </collision>
</link>

<link name="lf_femur_1">
  <inertial>
    <origin xyz="0.009181067699383441 5.714321216817447e-08 -0.04151323998476149" rpy="0 0 0"/>
    <mass value="0.3339508485314835"/>
    <inertia ixx="0.000356" iyy="0.000351" izz="2.2e-05" ixy="-0.0" iyz="-0.0" ixz="-2e-06"/>
  </inertial>
  <visual>
    <origin xyz="-0.0845 -0.004447 -0.077501" rpy="0 0 0"/>
    <geometry>
      <mesh filename="meshes/lf_femur_1.stl" scale="0.001 0.001 0.001"/>
    </geometry>
    <material name="yellow"/>
  </visual>
  <collision>
    <origin xyz="-0.0845 -0.004447 -0.077501" rpy="0 0 0"/>
    <geometry>
      <mesh filename="meshes/lf_femur_1.stl" scale="0.001 0.001 0.001"/>
    </geometry>
  </collision>
</link>

<link name="rf_femur_1">
  <inertial>
    <origin xyz="-0.009181067698290121 5.715328519825813e-08 -0.04151324005608822" rpy="0 0 0"/>
    <mass value="0.3339508505480848"/>
    <inertia ixx="0.000356" iyy="0.000351" izz="2.2e-05" ixy="0.0" iyz="-0.0" ixz="2e-06"/>
  </inertial>
  <visual>
    <origin xyz="0.0845 -0.004447 -0.077501" rpy="0 0 0"/>
    <geometry>
      <mesh filename="meshes/rf_femur_1.stl" scale="0.001 0.001 0.001"/>
    </geometry>
    <material name="yellow"/>
  </visual>
  <collision>
    <origin xyz="0.0845 -0.004447 -0.077501" rpy="0 0 0"/>
    <geometry>
      <mesh filename="meshes/rf_femur_1.stl" scale="0.001 0.001 0.001"/>
    </geometry>
  </collision>
</link>

<link name="rf_tibia_1">
  <inertial>
    <origin xyz="0.006000197106115546 -0.058134482220275646 0.05613412714957651" rpy="0 0 0"/>
    <mass value="0.3447546093376634"/>
    <inertia ixx="0.000577" iyy="0.000321" izz="0.000297" ixy="-0.0" iyz="0.000267" ixz="0.0"/>
  </inertial>
  <visual>
    <origin xyz="0.0995 -0.004447 0.022499" rpy="0 0 0"/>
    <geometry>
      <mesh filename="meshes/rf_tibia_1.stl" scale="0.001 0.001 0.001"/>
    </geometry>
    <material name="black"/>
  </visual>
  <collision>
    <origin xyz="0.0995 -0.004447 0.022499" rpy="0 0 0"/>
    <geometry>
      <mesh filename="meshes/rf_tibia_1.stl" scale="0.001 0.001 0.001"/>
    </geometry>
  </collision>
</link>

<link name="rr_tibia_1">
  <inertial>
    <origin xyz="0.0060001971061196535 -0.058134482220276895 0.05613430802773292" rpy="0 0 0"/>
    <mass value="0.3447546093376697"/>
    <inertia ixx="0.000577" iyy="0.000321" izz="0.000297" ixy="-0.0" iyz="0.000267" ixz="-0.0"/>
  </inertial>
  <visual>
    <origin xyz="0.0995 -0.004447 0.242799" rpy="0 0 0"/>
    <geometry>
      <mesh filename="meshes/rr_tibia_1.stl" scale="0.001 0.001 0.001"/>
    </geometry>
    <material name="black"/>
  </visual>
  <collision>
    <origin xyz="0.0995 -0.004447 0.242799" rpy="0 0 0"/>
    <geometry>
      <mesh filename="meshes/rr_tibia_1.stl" scale="0.001 0.001 0.001"/>
    </geometry>
  </collision>
</link>

<link name="lr_tibia_1">
  <inertial>
    <origin xyz="-0.0059999564309477366 -0.05813448222027471 0.05613430802772368" rpy="0 0 0"/>
    <mass value="0.34475460933765095"/>
    <inertia ixx="0.000577" iyy="0.000321" izz="0.000297" ixy="0.0" iyz="0.000267" ixz="0.0"/>
  </inertial>
  <visual>
    <origin xyz="-0.0995 -0.004447 0.242799" rpy="0 0 0"/>
    <geometry>
      <mesh filename="meshes/lr_tibia_1.stl" scale="0.001 0.001 0.001"/>
    </geometry>
    <material name="black"/>
  </visual>
  <collision>
    <origin xyz="-0.0995 -0.004447 0.242799" rpy="0 0 0"/>
    <geometry>
      <mesh filename="meshes/lr_tibia_1.stl" scale="0.001 0.001 0.001"/>
    </geometry>
  </collision>
</link>

<link name="lf_tibia_1">
  <inertial>
    <origin xyz="-0.0059999564309556885 -0.05813448222027249 0.056134127149572485" rpy="0 0 0"/>
    <mass value="0.34475460933764407"/>
    <inertia ixx="0.000577" iyy="0.000321" izz="0.000297" ixy="0.0" iyz="0.000267" ixz="-0.0"/>
  </inertial>
  <visual>
    <origin xyz="-0.0995 -0.004447 0.022499" rpy="0 0 0"/>
    <geometry>
      <mesh filename="meshes/lf_tibia_1.stl" scale="0.001 0.001 0.001"/>
    </geometry>
    <material name="black"/>
  </visual>
  <collision>
    <origin xyz="-0.0995 -0.004447 0.022499" rpy="0 0 0"/>
    <geometry>
      <mesh filename="meshes/lf_tibia_1.stl" scale="0.001 0.001 0.001"/>
    </geometry>
  </collision>
</link>

<joint name="Revolute 2" type="continuous">
  <origin xyz="-0.057 0.004647 0.057101" rpy="0 0 0"/>
  <parent link="base_link"/>
  <child link="fr_motor_1"/>
  <axis xyz="0.0 0.0 1.0"/>
</joint>

<joint name="Revolute 3" type="continuous">
  <origin xyz="0.057 0.004647 0.057101" rpy="0 0 0"/>
  <parent link="base_link"/>
  <child link="lf_motor_1"/>
  <axis xyz="0.0 -0.0 -1.0"/>
</joint>

<joint name="Revolute 4" type="continuous">
  <origin xyz="0.057 0.004647 -0.102199" rpy="0 0 0"/>
  <parent link="base_link"/>
  <child link="lr_motor_1"/>
  <axis xyz="-0.0 0.0 1.0"/>
</joint>

<joint name="Revolute 5" type="continuous">
  <origin xyz="-0.057 0.004647 -0.102199" rpy="0 0 0"/>
  <parent link="base_link"/>
  <child link="rr_motor_1"/>
  <axis xyz="0.0 -0.0 -1.0"/>
</joint>

<joint name="Revolute 6" type="continuous">
  <origin xyz="-0.0275 -0.0002 -0.0406" rpy="0 0 0"/>
  <parent link="rr_motor_1"/>
  <child link="lr_femur_1"/>
  <axis xyz="1.0 0.0 0.0"/>
</joint>

<joint name="Revolute 7" type="continuous">
  <origin xyz="0.0275 -0.0002 -0.0406" rpy="0 0 0"/>
  <parent link="lr_motor_1"/>
  <child link="rr_femur_1"/>
  <axis xyz="1.0 0.0 0.0"/>
</joint>

<joint name="Revolute 8" type="continuous">
  <origin xyz="0.0275 -0.0002 0.0204" rpy="0 0 0"/>
  <parent link="lf_motor_1"/>
  <child link="lf_femur_1"/>
  <axis xyz="1.0 0.0 0.0"/>
</joint>

<joint name="Revolute 9" type="continuous">
  <origin xyz="-0.0275 -0.0002 0.0204" rpy="0 0 0"/>
  <parent link="fr_motor_1"/>
  <child link="rf_femur_1"/>
  <axis xyz="1.0 0.0 0.0"/>
</joint>

<joint name="Revolute 10" type="continuous">
  <origin xyz="-0.015 0.0 -0.1" rpy="0 0 0"/>
  <parent link="rf_femur_1"/>
  <child link="rf_tibia_1"/>
  <axis xyz="-1.0 0.0 0.0"/>
</joint>

<joint name="Revolute 11" type="continuous">
  <origin xyz="-0.015 0.0 -0.1" rpy="0 0 0"/>
  <parent link="lr_femur_1"/>
  <child link="rr_tibia_1"/>
  <axis xyz="-1.0 0.0 0.0"/>
</joint>

<joint name="Revolute 12" type="continuous">
  <origin xyz="0.015 0.0 -0.1" rpy="0 0 0"/>
  <parent link="rr_femur_1"/>
  <child link="lr_tibia_1"/>
  <axis xyz="1.0 -0.0 0.0"/>
</joint>

<joint name="Revolute 13" type="continuous">
  <origin xyz="0.015 0.0 -0.1" rpy="0 0 0"/>
  <parent link="lf_femur_1"/>
  <child link="lf_tibia_1"/>
  <axis xyz="1.0 -0.0 0.0"/>
</joint>

</robot>
